[0m23:44:32.079919 [debug] [MainThread]: Sending event: {'category': 'dbt', 'action': 'invocation', 'label': 'start', 'context': [<snowplow_tracker.self_describing_json.SelfDescribingJson object at 0x7f2e6ec53cd0>, <snowplow_tracker.self_describing_json.SelfDescribingJson object at 0x7f2e6dce0850>, <snowplow_tracker.self_describing_json.SelfDescribingJson object at 0x7f2e6dce0610>]}


============================== 23:44:32.082723 | b4676c57-aa30-468b-b2b0-5083c8d9d108 ==============================
[0m23:44:32.082723 [info ] [MainThread]: Running with dbt=1.9.1
[0m23:44:32.083526 [debug] [MainThread]: running dbt with arguments {'printer_width': '80', 'indirect_selection': 'eager', 'write_json': 'True', 'log_cache_events': 'False', 'partial_parse': 'True', 'cache_selected_only': 'False', 'warn_error': 'None', 'version_check': 'True', 'fail_fast': 'False', 'log_path': 'logs', 'debug': 'False', 'profiles_dir': '/home/fede/.dbt', 'use_colors': 'True', 'use_experimental_parser': 'False', 'empty': 'False', 'quiet': 'False', 'no_print': 'None', 'log_format': 'default', 'static_parser': 'True', 'invocation_command': 'dbt run', 'warn_error_options': 'WarnErrorOptions(include=[], exclude=[])', 'target_path': 'None', 'introspect': 'True', 'send_anonymous_usage_stats': 'True'}
[0m23:44:32.084014 [error] [MainThread]: Encountered an error:
Runtime Error
  No dbt_project.yml found at expected path /home/fede/mlops/dbt/dbt_project.yml
  Verify that each entry within packages.yml (and their transitive dependencies) contains a file named dbt_project.yml
  
[0m23:44:32.084999 [debug] [MainThread]: Resource report: {"command_name": "run", "command_success": false, "command_wall_clock_time": 0.062169, "process_in_blocks": "0", "process_kernel_time": 0.212096, "process_mem_max_rss": "86308", "process_out_blocks": "16", "process_user_time": 1.424607}
[0m23:44:32.085468 [debug] [MainThread]: Command `dbt run` failed at 23:44:32.085357 after 0.06 seconds
[0m23:44:32.085932 [debug] [MainThread]: Sending event: {'category': 'dbt', 'action': 'invocation', 'label': 'end', 'context': [<snowplow_tracker.self_describing_json.SelfDescribingJson object at 0x7f2e6ec53cd0>, <snowplow_tracker.self_describing_json.SelfDescribingJson object at 0x7f2e6dce0b50>, <snowplow_tracker.self_describing_json.SelfDescribingJson object at 0x7f2e6dce0850>]}
[0m23:44:32.086316 [debug] [MainThread]: Flushing usage events
[0m23:44:32.739974 [debug] [MainThread]: An error was encountered while trying to flush usage events
